Workbook

Sheet A26 Pham Ngu Lao
A1: A26 Pham Ngu Lao
A2: Địa chỉ: Pham Ngu Lao, District 1, HCMC
A4: REPORT
B6: Mã đặt phòng | C6: Loại phòng | D6: Tên phòng | E6: Tên khách | F6: Ngày đến | G6: Ngày đi | H6: Tiền phòng | I6: Dịch vụ | J6: Tổng doanh thu | K6: Nợ trước | L6: Tiền mặt | M6: Thẻ tín dụng | N6: Chuyển khoản | O6: Công nợ | P6: Còn thiếu | Q6: SĐT | R6: Email | S6: CMND/Hộ chiếu | T6: Nguồn | U6: Thị trường | V6: Trạng thái | W6: Số hóa đơn | X6: Mã CMS | Y6: Giá trung bình | Z6: Số đêm
B7: 1 | C7: DELUXE-PNL | D7: 503 | E7: chị trang | F7: 22/05/24 09:40 | G7: 22/05/24 15:54 | H7: 0 | I7: 0 | J7: 0 | K7: 0 | L7: 0 | M7: 0 | N7: 0 | O7: 0 | P7: 0 | V7: CHECKOUT | W7: 1 | Y7: 0 | Z7: 1
B8: 9 | C8: DELUXE-PNL | D8: 303 | E8: Kayden | F8: 24/05/24 21:00 | G8: 25/05/24 08:59 | H8: 449000 | I8: 0 | J8: 449000 | K8: 0 | L8: 449000 | M8: 0 | N8: 0 | O8: 0 | P8: 0 | T8: Booked_CTV | V8: CHECKOUT | W8: 9 | Y8: 449000 | Z8: 1
B9: 5 | C9: DELUXE-PNL | D9: 403 | E9: Kang Byeong Jae | F9: 24/05/24 23:40 | G9: 25/05/24 09:00 | H9: 784534 | I9: 0 | J9: 784534 | K9: 0 | L9: 0 | M9: 0 | N9: 0 | O9: 784534 | P9: 0 | Q9: 821052846890 | T9: ONLINE | V9: CHECKOUT | W9: 5 | X9: HM5TCXPYJ5_LDCB1F | Y9: 784534 | Z9: 1
B10: 13 | C10: DELUXE-PNL | D10: 403 | E10: Long Hoàng | F10: 25/05/24 14:09 | G10: 25/05/24 14:09 | H10: 0 | I10: 0 | J10: 0 | K10: 0 | L10: 0 | M10: 0 | N10: 0 | O10: 0 | P10: 0 | T10: Booked_TA | V10: CHECKOUT | W10: 13 | Y10: 0 | Z10: 1
B11: 16 | C11: DELUXE-PNL | D11: 303 | E11: NG | F11: 25/05/24 15:04 | G11: 25/05/24 17:24 | H11: 449000 | I11: 0 | J11: 449000 | K11: 0 | L11: 0 | M11: 0 | N11: 449000 | O11: 0 | P11: 0 | T11: Booked_CTV | V11: CHECKOUT | W11: 16 | Y11: 449000 | Z11: 1
B12: 14 | C12: SUP-PNL | D12: 302 | E12: Đào Ngọc Mạnh | F12: 25/05/24 15:04 | G12: 25/05/24 18:42 | H12: 469000 | I12: 19000 | J12: 488000 | K12: 0 | L12: 19000 | M12: 0 | N12: 469000 | O12: 0 | P12: 0 | T12: Booked_CTV | V12: CHECKOUT | W12: 14 | Y12: 469000 | Z12: 1
B13: 12 | C13: STD-PNL | D13: 501 | E13: Tuấn | F13: 25/05/24 12:43 | G13: 26/05/24 08:35 | H13: 585000 | I13: 0 | J13: 585000 | K13: 0 | L13: 0 | M13: 0 | N13: 585000 | O13: 0 | P13: 0 | Q13: 0349743629 | T13: Booked_TA | V13: CHECKOUT | W13: 12 | Y13: 585000 | Z13: 1
B14: 8 | C14: SUP-Q-PNL | D14: 502 | E14: ASPA Baptiste | F14: 24/05/24 19:03 | G14: 26/05/24 08:35 | H14: 1530000 | I14: 0 | J14: 1530000 | K14: 0 | L14: 0 | M14: 0 | N14: 0 | O14: 1530000 | P14: 0 | T14: Booked_CTV | V14: CHECKOUT | W14: 8 | Y14: 765000 | Z14: 2
B15: 6 | C15: STD-PNL | D15: 301 | E15: Đặng Mai | F15: 25/05/24 20:06 | G15: 26/05/24 09:05 | H15: 463075 | I15: 0 | J15: 463075 | K15: 0 | L15: 0 | M15: 0 | N15: 0 | O15: 463075 | P15: 0 | Q15: 841212120676 | T15: ONLINE | V15: CHECKOUT | W15: 6 | X15: HMKHY5YWEM_LDCB1F | Y15: 463075 | Z15: 1
B16: 15 | C16: STD-PNL | D16: 401 | E16: Lý Minh Trí | F16: 25/05/24 14:16 | G16: 26/05/24 10:06 | H16: 580000 | I16: 0 | J16: 580000 | K16: 0 | L16: 580000 | M16: 0 | N16: 0 | O16: 0 | P16: 0 | Q16: 0932829180 | T16: Booked_CTV | V16: CHECKOUT | W16: 15 | Y16: 580000 | Z16: 1
B17: 11 | C17: STD-PNL | D17: 601 | E17: Lê Nhật | F17: 25/05/24 18:01 | G17: 26/05/24 11:00 | H17: 585000 | I17: 0 | J17: 585000 | K17: 0 | L17: 0 | M17: 0 | N17: 585000 | O17: 0 | P17: 0 | Q17: 0382156526 | T17: Booked_TA | V17: CHECKOUT | W17: 11 | Y17: 585000 | Z17: 1
B18: 17 | C18: SUP-Q-PNL | D18: 602 | E18: Russell | F18: 25/05/24 18:38 | G18: 26/05/24 11:00 | H18: 700000 | I18: 0 | J18: 700000 | K18: 0 | L18: 0 | M18: 0 | N18: 0 | O18: 700000 | P18: 0 | T18: Booked_CTV | V18: CHECKOUT | W18: 17 | Y18: 700000 | Z18: 1
B19: 19 | C19: STD-PNL | D19: 201 | E19: Quỳnh Như | F19: 25/05/24 22:35 | G19: 26/05/24 16:00 | H19: 825000 | I19: 0 | J19: 825000 | K19: 0 | L19: 240000 | M19: 0 | N19: 585000 | O19: 0 | P19: 0 | Q19: 0333038479 | T19: Booked_CTV | V19: CHECKOUT | W19: 19 | Y19: 825000 | Z19: 1
B20: 22 | C20: STD-PNL | D20: 501 | E20: Jo Phạm | F20: 26/05/24 13:59 | G20: 26/05/24 20:00 | H20: 575000 | I20: 0 | J20: 575000 | K20: 0 | L20: 0 | M20: 0 | N20: 0 | O20: 575000 | P20: 0 | Q20: 0906380089 | T20: Booked_TA | V20: CHECKOUT | W20: 22 | Y20: 575000 | Z20: 1
B21: 23 | C21: DELUXE-PNL | D21: 603 | E21: Lê Văn Thấu | F21: 26/05/24 19:44 | G21: 27/05/24 11:00 | H21: 585000 | I21: 0 | J21: 555000 | K21: 0 | L21: 0 | M21: 0 | N21: 555000 | O21: 0 | P21: 0 | S21: 038050003261 | T21: Booked_CTV | V21: CHECKOUT | W21: 24 | Y21: 585000 | Z21: 1
B22: 26 | C22: SUP-Q-PNL | D22: 602 | E22: Elvinas | F22: 26/05/24 19:31 | G22: 27/05/24 11:00 | H22: 804667 | I22: 0 | J22: 804667 | K22: 0 | L22: 0 | M22: 0 | N22: 0 | O22: 804667 | P22: 0 | T22: Công ty | V22: CHECKOUT | W22: 29 | Y22: 804667 | Z22: 1
B23: 10 | C23: SUP-PNL | D23: 402 | E23: Linh Đan | F23: 25/05/24 15:34 | G23: 27/05/24 11:30 | H23: 2042000 | I23: 200000 | J23: 2242000 | K23: 0 | L23: 1570000 | M23: 0 | N23: 672000 | O23: 0 | P23: 0 | Q23: 0989838633 | T23: Booked_CTV | V23: CHECKOUT | W23: 10 | Y23: 1021000 | Z23: 2
B24: 30 | C24: STD-PNL | D24: 501 | E24: Nghĩa Trịnh | F24: 27/05/24 12:00 | G24: 27/05/24 23:00 | H24: 529000 | I24: 0 | J24: 529000 | K24: 0 | L24: 0 | M24: 0 | N24: 529000 | O24: 0 | P24: 0 | Q24: 0395425614 | T24: Booked_TA | V24: CHECKOUT | W24: 33 | Y24: 529000 | Z24: 1
B25: 31 | C25: DELUXE-PNL | D25: 303 | E25: Võ Việt Trung | F25: 27/05/24 20:14 | G25: 28/05/24 09:09 | H25: 899000 | I25: 0 | J25: 809100 | K25: 0 | L25: 0 | M25: 0 | N25: 809100 | O25: 0 | P25: 0 | Q25: +84989109476 | R25: johntrung@gmail.com | T25: ONLINE | V25: CHECKOUT | W25: 34 | X25: 88825144721 | Y25: 899000 | Z25: 1
B26: 23 | C26: STD-PNL | D26: 601 | E26: Lê Ngọc Long | F26: 26/05/24 19:44 | G26: 28/05/24 09:34 | H26: 990000 | I26: 0 | J26: 990000 | K26: 0 | L26: 0 | M26: 0 | N26: 990000 | O26: 0 | P26: 0 | Q26: 0947865604 | S26: 038200032687 | T26: Booked_CTV | V26: CHECKOUT | W26: 23 | Y26: 495000 | Z26: 2
B27: 28 | C27: STD-PNL | D27: 501 | E27: Tien Tien | F27: 28/05/24 23:21 | G27: 29/05/24 10:37 | H27: 494000 | I27: 19000 | J27: 513000 | K27: 0 | L27: 19000 | M27: 0 | N27: 494000 | O27: 0 | P27: 0 | Q27: 0932006246 | T27: Booked_TA | V27: CHECKOUT | W27: 31 | Y27: 494000 | Z27: 1
B28: 24 | C28: SUP-PNL | D28: 402 | E28: phạm uyên thuỳ | F28: 27/05/24 14:33 | G28: 29/05/24 11:00 | H28: 1173334 | I28: 29000 | J28: 1202334 | K28: 0 | L28: 29000 | M28: 0 | N28: 1173334 | O28: 0 | P28: 0 | Q28: 0849127979 | T28: Booked_CTV | V28: CHECKOUT | W28: 26 | Y28: 586667 | Z28: 2
B29: 25 | C29: STD-PNL | D29: 401 | E29: Phan thị trang | F29: 26/05/24 23:40 | G29: 29/05/24 11:00 | H29: 1485000 | I29: 0 | J29: 1485000 | K29: 0 | L29: 0 | M29: 0 | N29: 1485000 | O29: 0 | P29: 0 | Q29: 0935954348 | T29: Booked_CTV | V29: CHECKOUT | W29: 28 | Y29: 495000 | Z29: 3
B30: 32 | C30: DELUXE-PNL | D30: 303 | E30: Tran huu Duc | F30: 28/05/24 17:12 | G30: 29/05/24 11:00 | H30: 899000 | I30: 0 | J30: 899000 | K30: 0 | L30: 0 | M30: 0 | N30: 899000 | O30: 0 | P30: 0 | Q30: +84 90 417 97 79 | T30: Booked_CTV | V30: CHECKOUT | W30: 35 | Y30: 899000 | Z30: 1
B31: 34 | C31: DELUXE-PNL | D31: 503 | E31: Bai Song | F31: 28/05/24 17:43 | G31: 29/05/24 11:00 | H31: 641656 | I31: 0 | J31: 641656 | K31: 0 | L31: 0 | M31: 0 | N31: 0 | O31: 641656 | P31: 0 | Q31: 8613216128828 | T31: ONLINE | V31: CHECKOUT | W31: 37 | X31: HM52SZN2WB_LDCB1F | Y31: 641656 | Z31: 1
B32: 33 | C32: DELUXE-PNL | D32: 403 | E32: Verma Shekher | F32: 28/05/24 11:15 | G32: 29/05/24 12:00 | H32: 467587 | I32: 39000 | J32: 506587 | K32: 0 | L32: 39000 | M32: 0 | N32: 0 | O32: 467587 | P32: 0 | V32: CHECKOUT | W32: 36 | Y32: 467587 | Z32: 1
B33: 39 | C33: STD-PNL | D33: 101 | E33: Nguyễn Trung Kiên | F33: 28/05/24 23:35 | G33: 29/05/24 12:00 | H33: 400000 | I33: 0 | J33: 400000 | K33: 0 | L33: 0 | M33: 0 | N33: 400000 | O33: 0 | P33: 0 | Q33: 0336280281 | T33: Booked_CTV | V33: CHECKOUT | W33: 42 | Y33: 400000 | Z33: 1
B34: 24 | C34: SUP-Q-PNL | D34: 602 | E34: phạm uyên thuỳ | F34: 27/05/24 14:33 | G34: 29/05/24 17:35 | H34: 1833334 | I34: 0 | J34: 1833334 | K34: 0 | L34: 580000 | M34: 0 | N34: 1253334 | O34: 0 | P34: 0 | Q34: 0849127979 | T34: Booked_CTV | V34: CHECKOUT | W34: 27 | Y34: 916667 | Z34: 2
B35: 24 | C35: SUP-Q-PNL | D35: 502 | E35: phạm uyên thuỳ | F35: 27/05/24 14:33 | G35: 29/05/24 17:36 | H35: 1833332 | I35: 0 | J35: 1833332 | K35: 0 | L35: 580000 | M35: 0 | N35: 1253332 | O35: 0 | P35: 0 | Q35: 0849127979 | T35: Booked_CTV | V35: CHECKOUT | W35: 25 | Y35: 916666 | Z35: 2
B36: 43 | C36: SUP-PNL | D36: 202 | E36: Nguyễn Thương | F36: 29/05/24 14:53 | G36: 29/05/24 17:38 | H36: 400000 | I36: 0 | J36: 400000 | K36: 0 | L36: 0 | M36: 0 | N36: 400000 | O36: 0 | P36: 0 | Q36: 0912465699 | T36: Booked_CTV | V36: CHECKOUT | W36: 46 | Y36: 400000 | Z36: 1
B37: 35 | C37: STD-PNL | D37: 601 | E37: Huỳnh Tuấn Kiệt | F37: 28/05/24 17:05 | G37: 30/05/24 08:06 | H37: 990000 | I37: 0 | J37: 990000 | K37: 0 | L37: 495000 | M37: 0 | N37: 495000 | O37: 0 | P37: 0 | Q37: 0914787909 | T37: Booked_CTV | V37: CHECKOUT | W37: 38 | Y37: 495000 | Z37: 2
B38: 37 | C38: SUP-PNL | D38: 102 | E38: Trần Thị Tường Vi | F38: 28/05/24 18:59 | G38: 30/05/24 10:57 | H38: 1100000 | I38: 0 | J38: 1100000 | K38: 0 | L38: 1100000 | M38: 0 | N38: 0 | O38: 0 | P38: 0 | T38: Booked_CTV | V38: CHECKOUT | W38: 40 | Y38: 550000 | Z38: 2
B39: 42 | C39: STD-PNL | D39: 501 | E39: Quốc Bảo | F39: 29/05/24 20:15 | G39: 30/05/24 11:00 | H39: 495000 | I39: 19000 | J39: 514000 | K39: 0 | L39: 264000 | M39: 0 | N39: 250000 | O39: 0 | P39: 0 | Q39: 0819200907 | T39: Booked_TA | V39: CHECKOUT | W39: 45 | Y39: 495000 | Z39: 1
B40: 46 | C40: STD-PNL | D40: 101 | E40: Choi Jae Min | F40: 30/05/24 12:30 | G40: 30/05/24 12:51 | H40: 349000 | I40: 0 | J40: 349000 | K40: 0 | L40: 349000 | M40: 0 | N40: 0 | O40: 0 | P40: 0 | T40: Booked_CTV | V40: CHECKOUT | W40: 51 | Y40: 349000 | Z40: 1
B41: 29 | C41: SUP-PNL | D41: 302 | E41: Ivy Van | F41: 27/05/24 15:12 | G41: 30/05/24 13:51 | H41: 1912000 | I41: 57000 | J41: 1969000 | K41: 0 | L41: 217000 | M41: 0 | N41: 1752000 | O41: 0 | P41: 0 | Q41: 0934 611 494 | T41: Booked_TA | V41: CHECKOUT | W41: 32 | Y41: 637333.33 | Z41: 3
B42: 48 | C42: STD-PNL | D42: 601 | E42: Hứa Bích Trân | F42: 30/05/24 14:46 | G42: 31/05/24 08:53 | H42: 349000 | I42: 0 | J42: 349000 | K42: 0 | L42: 349000 | M42: 0 | N42: 0 | O42: 0 | P42: 0 | T42: Booked_CTV | V42: CHECKOUT | W42: 53 | Y42: 349000 | Z42: 1
...

Sheet Chi tiết1
A1: Chi tiết về Trung bình của Giá trung bình - Nguồn: Booked_CTV
A3: Mã đặt phòng | B3: Loại phòng | C3: Tên phòng | D3: Tên khách | E3: Ngày đến | F3: Ngày đi | G3: Tiền phòng | H3: Dịch vụ | I3: Tổng doanh thu | J3: Nợ trước | K3: Tiền mặt | L3: Thẻ tín dụng | M3: Chuyển khoản | N3: Công nợ | O3: Còn thiếu | P3: SĐT | Q3: Email | R3: CMND/Hộ chiếu | S3: Nguồn | T3: Thị trường | U3: Trạng thái | V3: Số hóa đơn | W3: Mã CMS | X3: Giá trung bình | Y3: Số đêm
A4: 719 | B4: STD-PNL | C4: 401 | D4: Hằng Nguyễn | E4: 04/10/24 16:08 | F4: 08/10/24 11:00 | G4: 1908000 | H4: 0 | I4: 1908000 | J4: 0 | K4: 0 | L4: 0 | M4: 1908000 | N4: 0 | O4: 0 | P4: 0348514486 | Q4: Nguyenhanghd293@gmail.com | S4: Booked_CTV | U4: CHECKOUT | V4: 848 | X4: 477000 | Y4: 4
A5: 9 | B5: DELUXE-PNL | C5: 303 | D5: Kayden | E5: 24/05/24 21:00 | F5: 25/05/24 08:59 | G5: 449000 | H5: 0 | I5: 449000 | J5: 0 | K5: 449000 | L5: 0 | M5: 0 | N5: 0 | O5: 0 | S5: Booked_CTV | U5: CHECKOUT | V5: 9 | X5: 449000 | Y5: 1
A6: 715 | B6: STD-PNL | C6: 201 | D6: Hoàng Thị Anh | E6: 04/10/24 14:00 | F6: 07/10/24 08:27 | G6: 1752000 | H6: 0 | I6: 1752000 | J6: 0 | K6: 0 | L6: 0 | M6: 1752000 | N6: 0 | O6: 0 | P6: 0365170622 | R6: 038197002282 | S6: Booked_CTV | U6: CHECKOUT | V6: 844 | X6: 584000 | Y6: 3
A7: 716 | B7: SUP-PNL | C7: 202 | D7: Liên | E7: 04/10/24 19:39 | F7: 06/10/24 08:02 | G7: 1066000 | H7: 0 | I7: 1066000 | J7: 0 | K7: 532000 | L7: 0 | M7: 534000 | N7: 0 | O7: 0 | P7: 0914660204 | Q7: Baotranphamvu@gmail.com | S7: Booked_CTV | U7: CHECKOUT | V7: 845 | X7: 533000 | Y7: 2
A8: 16 | B8: DELUXE-PNL | C8: 303 | D8: NG | E8: 25/05/24 15:04 | F8: 25/05/24 17:24 | G8: 449000 | H8: 0 | I8: 449000 | J8: 0 | K8: 0 | L8: 0 | M8: 449000 | N8: 0 | O8: 0 | S8: Booked_CTV | U8: CHECKOUT | V8: 16 | X8: 449000 | Y8: 1
A9: 14 | B9: SUP-PNL | C9: 302 | D9: Đào Ngọc Mạnh | E9: 25/05/24 15:04 | F9: 25/05/24 18:42 | G9: 469000 | H9: 19000 | I9: 488000 | J9: 0 | K9: 19000 | L9: 0 | M9: 469000 | N9: 0 | O9: 0 | S9: Booked_CTV | U9: CHECKOUT | V9: 14 | X9: 469000 | Y9: 1
A10: 717 | B10: STD-PNL | C10: 301 | D10: Thảo Quyên | E10: 04/10/24 12:28 | F10: 04/10/24 17:16 | G10: 529000 | H10: 0 | I10: 529000 | J10: 0 | K10: 0 | L10: 0 | M10: 529000 | N10: 0 | O10: 0 | P10: 0938143339 | Q10: quyencntuk@gmail.com | S10: Booked_CTV | U10: CHECKOUT | V10: 846 | X10: 529000 | Y10: 1
A11: 8 | B11: SUP-Q-PNL | C11: 502 | D11: ASPA Baptiste | E11: 24/05/24 19:03 | F11: 26/05/24 08:35 | G11: 1530000 | H11: 0 | I11: 1530000 | J11: 0 | K11: 0 | L11: 0 | M11: 0 | N11: 1530000 | O11: 0 | S11: Booked_CTV | U11: CHECKOUT | V11: 8 | X11: 765000 | Y11: 2
A12: 718 | B12: STD-PNL | C12: 101 | D12: Kim | E12: 04/10/24 11:17 | F12: 04/10/24 12:31 | G12: 470000 | H12: 0 | I12: 470000 | J12: 0 | K12: 0 | L12: 0 | M12: 470000 | N12: 0 | O12: 0 | S12: Booked_CTV | U12: CHECKOUT | V12: 847 | X12: 470000 | Y12: 1
A13: 15 | B13: STD-PNL | C13: 401 | D13: Lý Minh Trí | E13: 25/05/24 14:16 | F13: 26/05/24 10:06 | G13: 580000 | H13: 0 | I13: 580000 | J13: 0 | K13: 580000 | L13: 0 | M13: 0 | N13: 0 | O13: 0 | P13: 0932829180 | S13: Booked_CTV | U13: CHECKOUT | V13: 15 | X13: 580000 | Y13: 1
A14: 713 | B14: DELUXE-PNL | C14: 103 | D14: Sơn Thị Lệ Hoa | E14: 03/10/24 17:11 | F14: 04/10/24 12:00 | G14: 700000 | H14: 0 | I14: 700000 | J14: 0 | K14: 700000 | L14: 0 | M14: 0 | N14: 0 | O14: 0 | S14: Booked_CTV | U14: CHECKOUT | V14: 842 | X14: 700000 | Y14: 1
A15: 17 | B15: SUP-Q-PNL | C15: 602 | D15: Russell | E15: 25/05/24 18:38 | F15: 26/05/24 11:00 | G15: 700000 | H15: 0 | I15: 700000 | J15: 0 | K15: 0 | L15: 0 | M15: 0 | N15: 700000 | O15: 0 | S15: Booked_CTV | U15: CHECKOUT | V15: 17 | X15: 700000 | Y15: 1
A16: 19 | B16: STD-PNL | C16: 201 | D16: Quỳnh Như | E16: 25/05/24 22:35 | F16: 26/05/24 16:00 | G16: 825000 | H16: 0 | I16: 825000 | J16: 0 | K16: 240000 | L16: 0 | M16: 585000 | N16: 0 | O16: 0 | P16: 0333038479 | S16: Booked_CTV | U16: CHECKOUT | V16: 19 | X16: 825000 | Y16: 1
A17: 697 | B17: SUP-PNL | C17: 402 | D17: Win Win Hla | E17: 01/10/24 17:39 | F17: 03/10/24 11:00 | G17: 1120000 | H17: 0 | I17: 1120000 | J17: 0 | K17: 1120000 | L17: 0 | M17: 0 | N17: 0 | O17: 0 | R17: MH099884 | S17: Booked_CTV | U17: CHECKOUT | V17: 825 | X17: 560000 | Y17: 2
A18: 23 | B18: DELUXE-PNL | C18: 603 | D18: Lê Văn Thấu | E18: 26/05/24 19:44 | F18: 27/05/24 11:00 | G18: 585000 | H18: 0 | I18: 555000 | J18: 0 | K18: 0 | L18: 0 | M18: 555000 | N18: 0 | O18: 0 | R18: 038050003261 | S18: Booked_CTV | U18: CHECKOUT | V18: 24 | X18: 585000 | Y18: 1
A19: 710 | B19: SUP-PNL | C19: 202 | D19: TRẦN QUỐC BẢO | E19: 03/10/24 08:51 | F19: 03/10/24 09:19 | G19: 525000 | H19: 0 | I19: 525000 | J19: 0 | K19: 525000 | L19: 0 | M19: 0 | N19: 0 | O19: 0 | P19: 0586534570 | S19: Booked_CTV | U19: CHECKOUT | V19: 838 | X19: 525000 | Y19: 1
A20: 10 | B20: SUP-PNL | C20: 402 | D20: Linh Đan | E20: 25/05/24 15:34 | F20: 27/05/24 11:30 | G20: 2042000 | H20: 200000 | I20: 2242000 | J20: 0 | K20: 1570000 | L20: 0 | M20: 672000 | N20: 0 | O20: 0 | P20: 0989838633 | S20: Booked_CTV | U20: CHECKOUT | V20: 10 | X20: 1021000 | Y20: 2
A21: 709 | B21: STD-PNL | C21: 301 | D21: TRẦN LÊ LỰU | E21: 02/10/24 20:08 | F21: 02/10/24 20:47 | G21: 350000 | H21: 0 | I21: 350000 | J21: 0 | K21: 350000 | L21: 0 | M21: 0 | N21: 0 | O21: 0 | S21: Booked_CTV | U21: CHECKOUT | V21: 837 | X21: 350000 | Y21: 1
A22: 707 | B22: STD-PNL | C22: 401 | D22: Minh | E22: 02/10/24 12:42 | F22: 02/10/24 15:14 | G22: 410000 | H22: 40000 | I22: 450000 | J22: 0 | K22: 450000 | L22: 0 | M22: 0 | N22: 0 | O22: 0 | S22: Booked_CTV | U22: CHECKOUT | V22: 835 | X22: 410000 | Y22: 1
A23: 23 | B23: STD-PNL | C23: 601 | D23: Lê Ngọc Long | E23: 26/05/24 19:44 | F23: 28/05/24 09:34 | G23: 990000 | H23: 0 | I23: 990000 | J23: 0 | K23: 0 | L23: 0 | M23: 990000 | N23: 0 | O23: 0 | P23: 0947865604 | R23: 038200032687 | S23: Booked_CTV | U23: CHECKOUT | V23: 23 | X23: 495000 | Y23: 2
A24: 700 | B24: STD-PNL | C24: 501 | D24: Dương Thiên Vũ | E24: 29/09/24 13:52 | F24: 02/10/24 09:13 | G24: 1437000 | H24: 0 | I24: 1437000 | J24: 0 | K24: 0 | L24: 0 | M24: 1437000 | N24: 0 | O24: 0 | S24: Booked_CTV | U24: CHECKOUT | V24: 828 | X24: 479000 | Y24: 3
A25: 24 | B25: SUP-PNL | C25: 402 | D25: phạm uyên thuỳ | E25: 27/05/24 14:33 | F25: 29/05/24 11:00 | G25: 1173334 | H25: 29000 | I25: 1202334 | J25: 0 | K25: 29000 | L25: 0 | M25: 1173334 | N25: 0 | O25: 0 | P25: 0849127979 | S25: Booked_CTV | U25: CHECKOUT | V25: 26 | X25: 586667 | Y25: 2
A26: 25 | B26: STD-PNL | C26: 401 | D26: Phan thị trang | E26: 26/05/24 23:40 | F26: 29/05/24 11:00 | G26: 1485000 | H26: 0 | I26: 1485000 | J26: 0 | K26: 0 | L26: 0 | M26: 1485000 | N26: 0 | O26: 0 | P26: 0935954348 | S26: Booked_CTV | U26: CHECKOUT | V26: 28 | X26: 495000 | Y26: 3
A27: 32 | B27: DELUXE-PNL | C27: 303 | D27: Tran huu Duc | E27: 28/05/24 17:12 | F27: 29/05/24 11:00 | G27: 899000 | H27: 0 | I27: 899000 | J27: 0 | K27: 0 | L27: 0 | M27: 899000 | N27: 0 | O27: 0 | P27: +84 90 417 97 79 | S27: Booked_CTV | U27: CHECKOUT | V27: 35 | X27: 899000 | Y27: 1
A28: 704 | B28: DELUXE-PNL | C28: 203 | D28: Hậu | E28: 01/10/24 18:37 | F28: 02/10/24 08:28 | G28: 760000 | H28: 0 | I28: 760000 | J28: 0 | K28: 0 | L28: 0 | M28: 760000 | N28: 0 | O28: 0 | S28: Booked_CTV | U28: CHECKOUT | V28: 832 | X28: 760000 | Y28: 1
A29: 706 | B29: STD-PNL | C29: 401 | D29: Nguyễn Thị Hoài Thương | E29: 01/10/24 18:46 | F29: 02/10/24 08:27 | G29: 494000 | H29: 0 | I29: 494000 | J29: 0 | K29: 0 | L29: 0 | M29: 494000 | N29: 0 | O29: 0 | S29: Booked_CTV | U29: CHECKOUT | V29: 834 | X29: 494000 | Y29: 1
A30: 39 | B30: STD-PNL | C30: 101 | D30: Nguyễn Trung Kiên | E30: 28/05/24 23:35 | F30: 29/05/24 12:00 | G30: 400000 | H30: 0 | I30: 400000 | J30: 0 | K30: 0 | L30: 0 | M30: 400000 | N30: 0 | O30: 0 | P30: 0336280281 | S30: Booked_CTV | U30: CHECKOUT | V30: 42 | X30: 400000 | Y30: 1
A31: 24 | B31: SUP-Q-PNL | C31: 602 | D31: phạm uyên thuỳ | E31: 27/05/24 14:33 | F31: 29/05/24 17:35 | G31: 1833334 | H31: 0 | I31: 1833334 | J31: 0 | K31: 580000 | L31: 0 | M31: 1253334 | N31: 0 | O31: 0 | P31: 0849127979 | S31: Booked_CTV | U31: CHECKOUT | V31: 27 | X31: 916667 | Y31: 2
A32: 24 | B32: SUP-Q-PNL | C32: 502 | D32: phạm uyên thuỳ | E32: 27/05/24 14:33 | F32: 29/05/24 17:36 | G32: 1833332 | H32: 0 | I32: 1833332 | J32: 0 | K32: 580000 | L32: 0 | M32: 1253332 | N32: 0 | O32: 0 | P32: 0849127979 | S32: Booked_CTV | U32: CHECKOUT | V32: 25 | X32: 916666 | Y32: 2
A33: 43 | B33: SUP-PNL | C33: 202 | D33: Nguyễn Thương | E33: 29/05/24 14:53 | F33: 29/05/24 17:38 | G33: 400000 | H33: 0 | I33: 400000 | J33: 0 | K33: 0 | L33: 0 | M33: 400000 | N33: 0 | O33: 0 | P33: 0912465699 | S33: Booked_CTV | U33: CHECKOUT | V33: 46 | X33: 400000 | Y33: 1
A34: 35 | B34: STD-PNL | C34: 601 | D34: Huỳnh Tuấn Kiệt | E34: 28/05/24 17:05 | F34: 30/05/24 08:06 | G34: 990000 | H34: 0 | I34: 990000 | J34: 0 | K34: 495000 | L34: 0 | M34: 495000 | N34: 0 | O34: 0 | P34: 0914787909 | S34: Booked_CTV | U34: CHECKOUT | V34: 38 | X34: 495000 | Y34: 2
A35: 37 | B35: SUP-PNL | C35: 102 | D35: Trần Thị Tường Vi | E35: 28/05/24 18:59 | F35: 30/05/24 10:57 | G35: 1100000 | H35: 0 | I35: 1100000 | J35: 0 | K35: 1100000 | L35: 0 | M35: 0 | N35: 0 | O35: 0 | S35: Booked_CTV | U35: CHECKOUT | V35: 40 | X35: 550000 | Y35: 2
A36: 705 | B36: STD-PNL | C36: 101 | D36: Thúy | E36: 01/10/24 15:33 | F36: 02/10/24 08:27 | G36: 494000 | H36: 0 | I36: 494000 | J36: 0 | K36: 0 | L36: 0 | M36: 494000 | N36: 0 | O36: 0 | R36: 056191010582 | S36: Booked_CTV | U36: CHECKOUT | V36: 833 | X36: 494000 | Y36: 1
A37: 46 | B37: STD-PNL | C37: 101 | D37: Choi Jae Min | E37: 30/05/24 12:30 | F37: 30/05/24 12:51 | G37: 349000 | H37: 0 | I37: 349000 | J37: 0 | K37: 349000 | L37: 0 | M37: 0 | N37: 0 | O37: 0 | S37: Booked_CTV | U37: CHECKOUT | V37: 51 | X37: 349000 | Y37: 1
A38: 701 | B38: DELUXE-PNL | C38: 103 | D38: Halliwell Bruce | E38: 30/09/24 11:44 | F38: 01/10/24 11:00 | G38: 650000 | H38: 0 | I38: 650000 | J38: 0 | K38: 650000 | L38: 0 | M38: 0 | N38: 0 | O38: 0 | S38: Booked_CTV | U38: CHECKOUT | V38: 829 | X38: 650000 | Y38: 1
A39: 48 | B39: STD-PNL | C39: 601 | D39: Hứa Bích Trân | E39: 30/05/24 14:46 | F39: 31/05/24 08:53 | G39: 349000 | H39: 0 | I39: 349000 | J39: 0 | K39: 349000 | L39: 0 | M39: 0 | N39: 0 | O39: 0 | S39: Booked_CTV | U39: CHECKOUT | V39: 53 | X39: 349000 | Y39: 1
A40: 36 | B40: STD-PNL | C40: 201 | D40: Nguyễn Xuân Hải | E40: 28/05/24 18:23 | F40: 31/05/24 08:55 | G40: 1290000 | H40: 0 | I40: 1290000 | J40: 0 | K40: 0 | L40: 0 | M40: 840000 | N40: 450000 | O40: 0 | P40: 0948653477 | S40: Booked_CTV | U40: CHECKOUT | V40: 39 | X40: 430000 | Y40: 3
A41: 52 | B41: STD-PNL | C41: 101 | D41: chị Mão - anh Cảnh | E41: 30/05/24 21:45 | F41: 31/05/24 09:11 | G41: 490000 | H41: 0 | I41: 490000 | J41: 0 | K41: 0 | L41: 0 | M41: 490000 | N41: 0 | O41: 0 | P41: 0845302686 | S41: Booked_CTV | U41: CHECKOUT | V41: 58 | X41: 490000 | Y41: 1
...

Sheet Visualize-6-months
A1: Room Analyst | H1: Channel Analyst
A2: June 2024 | H2: 45444
A3: Total Capacity | B3: Day | C3: Month | D3: Room Sold | E3: Occupancy | H3: Room Type | I3: Total Month | J3: Booking | K3: Agoda | L3: Airbnb | M3: Staff | N3: A26 web | O3: Facebook | P3: Walkin | Q3: Expedia | R3: Traveloka | S3: Travel Agent | T3: Klook
A4: Total Room | B4: =SUM(B5:B8) -> 20 | C4: =COUNTIF(June!E4:AH23,"<>Lock") -> 600 | D4: =COUNTIFS(June!E4:AH23, "<>",June!E4:AH23, "<>Lock") -> 310 | E4: =(D4/C4) -> 0.51666667 | H4: STD-PNL | I4: =SUM(J4:T4) -> 119 | J4: =COUNTIF(June!$E$4:$AH$9,J$40) -> 0 | K4: =COUNTIF(June!$E$4:$AH$9,K$40) -> 31 | L4: =COUNTIF(June!$E$4:$AH$9,L$40) -> 2 | M4: =COUNTIF(June!$E$4:$AH$9,M$40) -> 79 | N4: =COUNTIF(June!$E$4:$AH$9,N$40) -> 7 | O4: =COUNTIF(June!$E$4:$AH$9,O$40) -> 0 | P4: =COUNTIF(June!$E$4:$AH$9,P$40) -> 0 | Q4: =COUNTIF(June!$E$4:$AH$9,Q$40) -> 0 | ... T4: =COUNTIF(June!$E$4:$AH$9,T$40) -> 0
A5: STD-PNL | B5: 6 | C5: =COUNTIF(June!E4:AH9,"<>Lock") -> 180 | D5: =COUNTIFS(June!E4:AH9, "<>",June!E4:AH9, "<>Lock") -> 119 | E5: =(D5/C5) -> 0.66111111 | H5: SUP-PNL | I5: =SUM(J5:T5) -> 68 | J5: =COUNTIF(June!$E$10:$AH$13,J$40) -> 6 | K5: =COUNTIF(June!$E$10:$AH$13,K$40) -> 14 | L5: =COUNTIF(June!$E$10:$AH$13,L$40) -> 0 | M5: =COUNTIF(June!$E$10:$AH$13,M$40) -> 47 | N5: =COUNTIF(June!$E$10:$AH$13,N$40) -> 1 | O5: =COUNTIF(June!$E$10:$AH$13,O$40) -> 0 | P5: =COUNTIF(June!$E$10:$AH$13,P$40) -> 0 | Q5: =COUNTIF(June!$E$10:$AH$13,Q$40) -> 0 | ... T5: =COUNTIF(June!$E$10:$AH$13,T$40) -> 0
A6: SUP-PNL | B6: 4 | C6: =COUNTIF(June!E10:AH13,"<>Lock") -> 120 | D6: =COUNTIFS(June!E10:AH13, "<>",June!E10:AH13, "<>Lock") -> 68 | E6: =(D6/C6) -> 0.56666667 | H6: SUP-Q-PNL | I6: =SUM(J6:T6) -> 35 | J6: =COUNTIF(June!$E$14:$AH$16,J$40) -> 2 | K6: =COUNTIF(June!$E$14:$AH$16,K$40) -> 5 | L6: =COUNTIF(June!$E$14:$AH$16,L$40) -> 6 | M6: =COUNTIF(June!$E$14:$AH$16,M$40) -> 19 | N6: =COUNTIF(June!$E$14:$AH$16,N$40) -> 2 | O6: =COUNTIF(June!$E$14:$AH$16,O$40) -> 1 | P6: =COUNTIF(June!$E$14:$AH$16,P$40) -> 0 | Q6: =COUNTIF(June!$E$14:$AH$16,Q$40) -> 0 | ... T6: =COUNTIF(June!$E$14:$AH$16,T$40) -> 0
A7: SUP-Q-PNL | B7: 3 | C7: =COUNTIF(June!E14:AH16,"<>Lock") -> 90 | D7: =COUNTIFS(June!E14:AH16, "<>",June!E14:AH16, "<>Lock") -> 35 | E7: =(D7/C7) -> 0.38888889 | H7: DELUXE - PNL | I7: =SUM(J7:T7) -> 88 | J7: =COUNTIF(June!$E$17:$AH$23,J$40) -> 0 | K7: =COUNTIF(June!$E$17:$AH$23,K$40) -> 0 | L7: =COUNTIF(June!$E$17:$AH$23,L$40) -> 19 | M7: =COUNTIF(June!$E$17:$AH$23,M$40) -> 55 | N7: =COUNTIF(June!$E$17:$AH$23,N$40) -> 14 | O7: =COUNTIF(June!$E$17:$AH$23,O$40) -> 0 | P7: =COUNTIF(June!$E$17:$AH$23,P$40) -> 0 | Q7: =COUNTIF(June!$E$17:$AH$23,Q$40) -> 0 | ... T7: =COUNTIF(June!$E$17:$AH$23,T$40) -> 0
A8: DELUXE-PNL | B8: 7 | C8: =COUNTIF(June!E17:AH23,"<>Lock") -> 210 | D8: =COUNTIFS(June!E17:AH23, "<>",June!E17:AH23, "<>Lock") -> 88 | E8: =(D8/C8) -> 0.41904762
H9: 45474
A10: July 2024 | H10: Room Type | I10: Total Month | J10: Booking | K10: Agoda | L10: Airbnb | M10: Staff | N10: A26 web | O10: Facebook | P10: Walkin | Q10: Expedia | R10: Traveloka | S10: Travel Agent | T10: Klook
A11: Total Capacity | B11: Day | C11: Month | D11: Room Sold | E11: Occupancy | H11: STD-PNL | I11: =SUM(J11:T11) -> 161 | J11: =COUNTIF(July!$E$4:$AI$9,J$40) -> 3 | K11: =COUNTIF(July!$E$4:$AI$9,K$40) -> 42 | L11: =COUNTIF(July!$E$4:$AI$9,L$40) -> 4 | M11: =COUNTIF(July!$E$4:$AI$9,M$40) -> 108 | N11: =COUNTIF(July!$E$4:$AI$9,N$40) -> 2 | O11: =COUNTIF(July!$E$4:$AI$9,O$40) -> 0 | P11: =COUNTIF(July!$E$4:$AI$9,P$40) -> 0 | Q11: =COUNTIF(July!$E$4:$AI$9,Q$40) -> 0 | ... T11: =COUNTIF(July!$E$4:$AI$9,T$40) -> 0
A12: Total Room | B12: =SUM(B13:B16) -> 20 | C12: =COUNTIF(July!E4:AI23,"<>Lock") -> 620 | D12: =COUNTIFS(July!E4:AI23, "<>",July!E4:AI23, "<>Lock") -> 440 | E12: =(D12/C12) -> 0.70967742 | H12: SUP-PNL | I12: =SUM(J12:T12) -> 89 | J12: =COUNTIF(July!$E$10:$AI$13,J$40) -> 6 | K12: =COUNTIF(July!$E$10:$AI$13,K$40) -> 5 | L12: =COUNTIF(July!$E$10:$AI$13,L$40) -> 9 | M12: =COUNTIF(July!$E$10:$AI$13,M$40) -> 66 | N12: =COUNTIF(July!$E$10:$AI$13,N$40) -> 0 | O12: =COUNTIF(July!$E$10:$AI$13,O$40) -> 0 | P12: =COUNTIF(July!$E$10:$AI$13,P$40) -> 0 | Q12: =COUNTIF(July!$E$10:$AI$13,Q$40) -> 3 | ... T12: =COUNTIF(July!$E$10:$AI$13,T$40) -> 0
A13: STD-PNL | B13: 6 | C13: =COUNTIF(July!E4:AI9,"<>Lock") -> 186 | D13: =COUNTIFS(July!E4:AI9, "<>",July!E4:AI9, "<>Lock") -> 161 | E13: =(D13/C13) -> 0.8655914 | H13: SUP-Q-PNL | I13: =SUM(J13:T13) -> 53 | J13: =COUNTIF(July!$E$14:$AI$16,J$40) -> 3 | K13: =COUNTIF(July!$E$14:$AI$16,K$40) -> 3 | L13: =COUNTIF(July!$E$14:$AI$16,L$40) -> 3 | M13: =COUNTIF(July!$E$14:$AI$16,M$40) -> 37 | N13: =COUNTIF(July!$E$14:$AI$16,N$40) -> 7 | O13: =COUNTIF(July!$E$14:$AI$16,O$40) -> 0 | P13: =COUNTIF(July!$E$14:$AI$16,P$40) -> 0 | Q13: =COUNTIF(July!$E$14:$AI$16,Q$40) -> 0 | ... T13: =COUNTIF(July!$E$14:$AI$16,T$40) -> 0
A14: SUP-PNL | B14: 4 | C14: =COUNTIF(July!E10:AI13,"<>Lock") -> 124 | D14: =COUNTIFS(July!E10:AI13, "<>",July!E10:AI13, "<>Lock") -> 89 | E14: =(D14/C14) -> 0.71774194 | H14: DELUXE - PNL | I14: =SUM(J14:T14) -> 137 | J14: =COUNTIF(July!$E$17:$AI$23,J$40) -> 1 | K14: =COUNTIF(July!$E$17:$AI$23,K$40) -> 12 | L14: =COUNTIF(July!$E$17:$AI$23,L$40) -> 5 | M14: =COUNTIF(July!$E$17:$AI$23,M$40) -> 118 | N14: =COUNTIF(July!$E$17:$AI$23,N$40) -> 1 | O14: =COUNTIF(July!$E$17:$AI$23,O$40) -> 0 | P14: =COUNTIF(July!$E$17:$AI$23,P$40) -> 0 | Q14: =COUNTIF(July!$E$17:$AI$23,Q$40) -> 0 | ... T14: =COUNTIF(July!$E$17:$AI$23,T$40) -> 0
A15: SUP-Q-PNL | B15: 3 | C15: =COUNTIF(July!E14:AI16,"<>Lock") -> 93 | D15: =COUNTIFS(July!E14:AI16, "<>",July!E14:AI16, "<>Lock") -> 53 | E15: =(D15/C15) -> 0.56989247
A16: DELUXE-PNL | B16: 7 | C16: =COUNTIF(July!E17:AI23,"<>Lock") -> 217 | D16: =COUNTIFS(July!E17:AI23, "<>",July!E17:AI23, "<>Lock") -> 137 | E16: =(D16/C16) -> 0.63133641
H17: 45505
A18: August 2024 | H18: Room Type | I18: Total Month | J18: Booking | K18: Agoda | L18: Airbnb | M18: Staff | N18: A26 web | O18: Facebook | P18: Walkin | Q18: Expedia | R18: Traveloka | S18: Travel Agent | T18: Klook
A19: Total Capacity | B19: Day | C19: Month | D19: Room Sold | E19: Occupancy | H19: STD-PNL | I19: =SUM(J19:T19) -> 112 | J19: =COUNTIF(August!$E$4:$AI$9,J$40) -> 7 | K19: =COUNTIF(August!$E$4:$AI$9,K$40) -> 14 | L19: =COUNTIF(August!$E$4:$AI$9,L$40) -> 3 | M19: =COUNTIF(August!$E$4:$AI$9,M$40) -> 88 | N19: =COUNTIF(August!$E$4:$AI$9,N$40) -> 0 | O19: =COUNTIF(August!$E$4:$AI$9,O$40) -> 0 | P19: =COUNTIF(August!$E$4:$AI$9,P$40) -> 0 | Q19: =COUNTIF(August!$E$4:$AI$9,Q$40) -> 0 | ... T19: =COUNTIF(August!$E$4:$AI$9,T$40) -> 0
A20: Total Room | B20: =SUM(B21:B24) -> 20 | C20: =COUNTIF(August!E4:AI23,"<>Lock") -> 608 | D20: =COUNTIFS(August!E4:AI23, "<>",August!E4:AI23, "<>Lock") -> 284 | E20: =(D20/C20) -> 0.46710526 | H20: SUP-PNL | I20: =SUM(J20:T20) -> 54 | J20: =COUNTIF(August!$E$10:$AI$13,J$40) -> 1 | K20: =COUNTIF(August!$E$10:$AI$13,K$40) -> 2 | L20: =COUNTIF(August!$E$10:$AI$13,L$40) -> 7 | M20: =COUNTIF(August!$E$10:$AI$13,M$40) -> 44 | N20: =COUNTIF(August!$E$10:$AI$13,N$40) -> 0 | O20: =COUNTIF(August!$E$10:$AI$13,O$40) -> 0 | P20: =COUNTIF(August!$E$10:$AI$13,P$40) -> 0 | Q20: =COUNTIF(August!$E$10:$AI$13,Q$40) -> 0 | ... T20: =COUNTIF(August!$E$10:$AI$13,T$40) -> 0
A21: STD-PNL | B21: 6 | C21: =COUNTIF(August!E4:AI9,"<>Lock") -> 186 | D21: =COUNTIFS(August!E4:AI9, "<>",August!E4:AI9, "<>Lock") -> 112 | E21: =(D21/C21) -> 0.60215054 | H21: SUP-Q-PNL | I21: =SUM(J21:T21) -> 44 | J21: =COUNTIF(August!$E$14:$AI$16,J$40) -> 0 | K21: =COUNTIF(August!$E$14:$AI$16,K$40) -> 4 | L21: =COUNTIF(August!$E$14:$AI$16,L$40) -> 0 | M21: =COUNTIF(August!$E$14:$AI$16,M$40) -> 35 | N21: =COUNTIF(August!$E$14:$AI$16,N$40) -> 0 | O21: =COUNTIF(August!$E$14:$AI$16,O$40) -> 0 | P21: =COUNTIF(August!$E$14:$AI$16,P$40) -> 0 | Q21: =COUNTIF(August!$E$14:$AI$16,Q$40) -> 2 | ... T21: =COUNTIF(August!$E$14:$AI$16,T$40) -> 3
A22: SUP-PNL | B22: 4 | C22: =COUNTIF(August!E10:AI13,"<>Lock") -> 124 | D22: =COUNTIFS(August!E10:AI13, "<>",August!E10:AI13, "<>Lock") -> 54 | E22: =(D22/C22) -> 0.43548387 | H22: DELUXE - PNL | I22: =SUM(J22:T22) -> 74 | J22: =COUNTIF(August!$E$17:$AI$23,J$40) -> 3 | K22: =COUNTIF(August!$E$17:$AI$23,K$40) -> 4 | L22: =COUNTIF(August!$E$17:$AI$23,L$40) -> 5 | M22: =COUNTIF(August!$E$17:$AI$23,M$40) -> 52 | N22: =COUNTIF(August!$E$17:$AI$23,N$40) -> 0 | O22: =COUNTIF(August!$E$17:$AI$23,O$40) -> 0 | P22: =COUNTIF(August!$E$17:$AI$23,P$40) -> 0 | Q22: =COUNTIF(August!$E$17:$AI$23,Q$40) -> 10 | ... T22: =COUNTIF(August!$E$17:$AI$23,T$40) -> 0
A23: SUP-Q-PNL | B23: 3 | C23: =COUNTIF(August!E14:AI16,"<>Lock") -> 93 | D23: =COUNTIFS(August!E14:AI16, "<>",August!E14:AI16, "<>Lock") -> 44 | E23: =(D23/C23) -> 0.47311828
A24: DELUXE-PNL | B24: 7 | C24: =COUNTIF(August!E17:AI23,"<>Lock") -> 205 | D24: =COUNTIFS(August!E17:AI23, "<>",August!E17:AI23, "<>Lock") -> 74 | E24: =(D24/C24) -> 0.36097561
H25: 45536
A26: Sep 2024 | H26: Room Type | I26: Total Month | J26: Booking | K26: Agoda | L26: Airbnb | M26: Staff | N26: A26 web | O26: Facebook | P26: Walkin | Q26: Expedia | R26: Traveloka | S26: Travel Agent | T26: Klook
A27: Total Capacity | B27: Day | C27: Month | D27: Room Sold | E27: Occupancy | H27: STD-PNL | I27: =SUM(J27:T27) -> 107 | J27: =COUNTIF(September!$E$4:$AH$9,J$40) -> 22 | K27: =COUNTIF(September!$E$4:$AH$9,K$40) -> 3 | L27: =COUNTIF(September!$E$4:$AH$9,L$40) -> 1 | M27: =COUNTIF(September!$E$4:$AH$9,M$40) -> 68 | N27: =COUNTIF(September!$E$4:$AH$9,N$40) -> 6 | O27: =COUNTIF(September!$E$4:$AH$9,O$40) -> 0 | P27: =COUNTIF(September!$E$4:$AH$9,P$40) -> 0 | Q27: =COUNTIF(September!$E$4:$AH$9,Q$40) -> 5 | ... T27: =COUNTIF(September!$E$4:$AH$9,T$40) -> 1
A28: Total Room | B28: =SUM(B29:B32) -> 19 | C28: =COUNTIF(September!E4:AH23,"<>Lock") -> 567 | D28: =COUNTIFS(September!E4:AH23, "<>", September!E4:AH23, "<>Lock") -> 267 | E28: =(D28/C28) -> 0.47089947 | H28: SUP-PNL | I28: =SUM(J28:T28) -> 50 | J28: =COUNTIF(September!$E$10:$AH$13,J$40) -> 7 | K28: =COUNTIF(September!$E$10:$AH$13,K$40) -> 1 | L28: =COUNTIF(September!$E$10:$AH$13,L$40) -> 0 | M28: =COUNTIF(September!$E$10:$AH$13,M$40) -> 37 | N28: =COUNTIF(September!$E$10:$AH$13,N$40) -> 0 | O28: =COUNTIF(September!$E$10:$AH$13,O$40) -> 0 | P28: =COUNTIF(September!$E$10:$AH$13,P$40) -> 0 | Q28: =COUNTIF(September!$E$10:$AH$13,Q$40) -> 5 | ... T28: =COUNTIF(September!$E$10:$AH$13,T$40) -> 0
A29: STD-PNL | B29: 6 | C29: =COUNTIF(September!E4:AH9,"<>Lock") -> 180 | D29: =COUNTIFS(September!E4:AH9, "<>", September!E4:AH9, "<>Lock") -> 107 | E29: =(D29/C29) -> 0.59444444 | H29: SUP-Q-PNL | I29: =SUM(J29:T29) -> 29 | J29: =COUNTIF(September!$E$14:$AH$16,J$40) -> 4 | K29: =COUNTIF(September!$E$14:$AH$16,K$40) -> 1 | L29: =COUNTIF(September!$E$14:$AH$16,L$40) -> 1 | M29: =COUNTIF(September!$E$14:$AH$16,M$40) -> 19 | N29: =COUNTIF(September!$E$14:$AH$16,N$40) -> 0 | O29: =COUNTIF(September!$E$14:$AH$16,O$40) -> 0 | P29: =COUNTIF(September!$E$14:$AH$16,P$40) -> 0 | Q29: =COUNTIF(September!$E$14:$AH$16,Q$40) -> 4 | ... T29: =COUNTIF(September!$E$14:$AH$16,T$40) -> 0
A30: SUP-PNL | B30: 4 | C30: =COUNTIF(September!E10:AH13,"<>Lock") -> 120 | D30: =COUNTIFS(September!E10:AH13, "<>",September!E10:AH13, "<>Lock") -> 50 | E30: =(D30/C30) -> 0.41666667 | H30: DELUXE - PNL | I30: =SUM(J30:T30) -> 81 | J30: =COUNTIF(September!$E$17:$AH$23,J$40) -> 9 | K30: =COUNTIF(September!$E$17:$AH$23,K$40) -> 0 | L30: =COUNTIF(September!$E$17:$AH$23,L$40) -> 13 | M30: =COUNTIF(September!$E$17:$AH$23,M$40) -> 53 | N30: =COUNTIF(September!$E$17:$AH$23,N$40) -> 0 | O30: =COUNTIF(September!$E$17:$AH$23,O$40) -> 0 | P30: =COUNTIF(September!$E$17:$AH$23,P$40) -> 0 | Q30: =COUNTIF(September!$E$17:$AH$23,Q$40) -> 6 | ... T30: =COUNTIF(September!$E$17:$AH$23,T$40) -> 0
A31: SUP-Q-PNL | B31: 3 | C31: =COUNTIF(September!E14:AH16,"<>Lock") -> 87 | D31: =COUNTIFS(September!E14:AH16, "<>",September!E14:AH16, "<>Lock") -> 29 | E31: =(D31/C31) -> 0.33333333
A32: DELUXE-PNL | B32: 6 | C32: =COUNTIF(September!E17:AH23,"<>Lock") -> 180 | D32: =COUNTIFS(September!E17:AH23, "<>",September!E17:AH23, "<>Lock") -> 81 | E32: =(D32/C32) -> 0.45
H33: 45566
A34: Oct 2024 | H34: Room Type | I34: Total Month | J34: Booking | K34: Agoda | L34: Airbnb | M34: Staff | N34: A26 web | O34: Facebook | P34: Walkin | Q34: Expedia | R34: Traveloka | S34: Travel Agent | T34: Klook
A35: Total Capacity | B35: Day | C35: Month | D35: Room Sold | E35: Occupancy | H35: STD-PNL | I35: =SUM(J35:T35) -> 49 | J35: =COUNTIF(October!$E$4:$AI$9,J$40) -> 9 | K35: =COUNTIF(October!$E$4:$AI$9,K$40) -> 1 | L35: =COUNTIF(October!$E$4:$AI$9,L$40) -> 1 | M35: =COUNTIF(October!$E$4:$AI$9,M$40) -> 29 | N35: =COUNTIF(October!$E$4:$AI$9,N$40) -> 1 | O35: =COUNTIF(October!$E$4:$AI$9,O$40) -> 0 | P35: =COUNTIF(October!$E$4:$AI$9,P$40) -> 0 | Q35: =COUNTIF(October!$E$4:$AI$9,Q$40) -> 8 | ... T35: =COUNTIF(October!$E$4:$AI$9,T$40) -> 0
A36: Total Room | B36: =SUM(B37:B40) -> 19 | C36: =COUNTIF(October!E4:AI23,"<>Lock") -> 558 | D36: =COUNTIFS(October!E4:AI23, "<>",October!E4:AI23, "<>Lock") -> 105 | E36: =(D36/C36) -> 0.18817204 | H36: SUP-PNL | I36: =SUM(J36:T36) -> 21 | J36: =COUNTIF(October!$E$10:$AI$13,J$40) -> 9 | K36: =COUNTIF(October!$E$10:$AI$13,K$40) -> 1 | L36: =COUNTIF(October!$E$10:$AI$13,L$40) -> 0 | M36: =COUNTIF(October!$E$10:$AI$13,M$40) -> 11 | N36: =COUNTIF(October!$E$10:$AI$13,N$40) -> 0 | O36: =COUNTIF(October!$E$10:$AI$13,O$40) -> 0 | P36: =COUNTIF(October!$E$10:$AI$13,P$40) -> 0 | Q36: =COUNTIF(October!$E$10:$AI$13,Q$40) -> 0 | ... T36: =COUNTIF(October!$E$10:$AI$13,T$40) -> 0
A37: STD-PNL | B37: 6 | C37: =COUNTIF(October!E4:AI9,"<>Lock") -> 186 | D37: =COUNTIFS(October!E4:AI9, "<>",October!E4:AI9, "<>Lock") -> 49 | E37: =(D37/C37) -> 0.26344086 | H37: SUP-Q-PNL | I37: =SUM(J37:T37) -> 8 | J37: =COUNTIF(October!$E$14:$AI$16,J$40) -> 0 | K37: =COUNTIF(October!$E$14:$AI$16,K$40) -> 0 | L37: =COUNTIF(October!$E$14:$AI$16,L$40) -> 3 | M37: =COUNTIF(October!$E$14:$AI$16,M$40) -> 3 | N37: =COUNTIF(October!$E$14:$AI$16,N$40) -> 0 | O37: =COUNTIF(October!$E$14:$AI$16,O$40) -> 0 | P37: =COUNTIF(October!$E$14:$AI$16,P$40) -> 0 | Q37: =COUNTIF(October!$E$14:$AI$16,Q$40) -> 2 | ... T37: =COUNTIF(October!$E$14:$AI$16,T$40) -> 0
A38: SUP-PNL | B38: 4 | C38: =COUNTIF(October!E10:AI13,"<>Lock") -> 124 | D38: =COUNTIFS(October!E10:AI13, "<>",October!E10:AI13, "<>Lock") -> 21 | E38: =(D38/C38) -> 0.16935484 | H38: DELUXE - PNL | I38: =SUM(J38:T38) -> 27 | J38: =COUNTIF(October!$E$17:$AI$23,J$40) -> 9 | K38: =COUNTIF(October!$E$17:$AI$23,K$40) -> 0 | L38: =COUNTIF(October!$E$17:$AI$23,L$40) -> 3 | M38: =COUNTIF(October!$E$17:$AI$23,M$40) -> 15 | N38: =COUNTIF(October!$E$17:$AI$23,N$40) -> 0 | O38: =COUNTIF(October!$E$17:$AI$23,O$40) -> 0 | P38: =COUNTIF(October!$E$17:$AI$23,P$40) -> 0 | Q38: =COUNTIF(October!$E$17:$AI$23,Q$40) -> 0 | ... T38: =COUNTIF(October!$E$17:$AI$23,T$40) -> 0
A39: SUP-Q-PNL | B39: 3 | C39: =COUNTIF(October!E14:AI16,"<>Lock") -> 62 | D39: =COUNTIFS(October!E14:AI16, "<>",October!E14:AI16, "<>Lock") -> 8 | E39: =(D39/C39) -> 0.12903226
A40: DELUXE-PNL | B40: 6 | C40: =COUNTIF(October!E17:AI23,"<>Lock") -> 186 | D40: =COUNTIFS(October!E17:AI23, "<>",October!E17:AI23, "<>Lock") -> 27 | E40: =(D40/C40) -> 0.14516129 | J40: Booked_BK | K40: Booked_Ag | L40: Booked_BNB | M40: Booked_CTV | N40: Booked_Web | O40: Booked_FB | P40: Booked_WK | Q40: Booked_Ex | R40: Booked_LK | S40: Booked_TA | T40: Booked_KL
...

Sheet August
B1: A26 PNL | E1: August 2024
E2: Thu | F2: Fri | G2: Sat | H2: Sun | I2: Mon | J2: Tue | K2: Wed | L2: Thu | M2: Fri | N2: Sat | O2: Sun | P2: Mon | Q2: Tue | R2: Wed | S2: Thu | T2: Fri | U2: Sat | V2: Sun | W2: Mon | X2: Tue | Y2: Wed | Z2: Thu | AA2: Fri | AB2: Sat | AC2: Sun | AD2: Mon | AE2: Tue | AF2: Wed | AG2: Thu | AH2: Fri | AI2: Sat
A3: No | B3: Room type | C3: Room No | D3: Capacity (pax) | E3: 45505 | F3: 45506 | G3: 45507 | H3: 45508 | I3: 45509 | J3: 45510 | K3: 45511 | L3: 45512 | M3: 45513 | N3: 45514 | O3: 45515 | P3: 45516 | Q3: 45517 | R3: 45518 | S3: 45519 | T3: 45520 | U3: 45521 | V3: 45522 | W3: 45523 | X3: 45524 | Y3: 45525 | Z3: 45526 | AA3: 45527 | AB3: 45528 | AC3: 45529 | AD3: 45530 | AE3: 45531 | AF3: 45532 | AG3: 45533 | AH3: 45534 | AI3: 45535
A4: 1 | B4: STD-PNL | C4: 101 | D4: 2 | M4: Booked_CTV | N4: Booked_CTV | O4: Booked_BK | S4: Booked_Ag | T4: Booked_CTV | X4: Booked_CTV | AA4: Booked_CTV | AB4: Booked_CTV | AC4: Booked_CTV | AF4: Booked_CTV
A5: 2 | B5: STD-PNL | C5: 201 | D5: 2 | E5: Booked_Ag | F5: Booked_Ag | G5: Booked_Ag | H5: Booked_CTV | I5: Booked_CTV | M5: Booked_CTV | N5: Booked_CTV | O5: Booked_BK | P5: Booked_BK | Q5: Booked_BK | R5: Booked_BK | S5: Booked_CTV | T5: Booked_CTV | U5: Booked_CTV | V5: Booked_CTV | W5: Booked_CTV | AB5: Booked_CTV | AC5: Booked_CTV | AD5: Booked_CTV | AE5: Booked_CTV | AF5: Booked_CTV | AG5: Booked_CTV | AI5: Booked_CTV
A6: 3 | B6: STD-PNL | C6: 301 | D6: 2 | E6: Booked_CTV | F6: Booked_CTV | G6: Booked_CTV | H6: Booked_CTV | J6: Booked_CTV | K6: Booked_CTV | N6: Booked_Ag | O6: Booked_Ag | P6: Booked_CTV | S6: Booked_BK | T6: Booked_CTV | U6: Booked_CTV | W6: Booked_CTV | AB6: Booked_CTV | AC6: Booked_CTV | AD6: Booked_CTV | AE6: Booked_CTV | AF6: Booked_CTV | AG6: Booked_CTV | AH6: Booked_Ag | AI6: Booked_Ag
A7: 4 | B7: STD-PNL | C7: 401 | D7: 2 | E7: Booked_CTV | F7: Booked_CTV | G7: Booked_CTV | K7: Booked_BK | O7: Booked_Ag | P7: Booked_Ag | Q7: Booked_Ag | R7: Booked_Ag | S7: Booked_CTV | T7: Booked_CTV | U7: Booked_CTV | V7: Booked_CTV | Y7: Booked_CTV | Z7: Booked_CTV | AA7: Booked_CTV | AB7: Booked_CTV | AC7: Booked_CTV | AE7: Booked_CTV | AG7: Booked_Ag | AI7: Booked_CTV
A8: 5 | B8: STD-PNL | C8: 501 | D8: 2 | F8: Booked_CTV | I8: Booked_CTV | J8: Booked_CTV | K8: Booked_CTV | L8: Booked_CTV | O8: Booked_CTV | P8: Booked_Ag | T8: Booked_CTV | U8: Booked_CTV | W8: Booked_CTV | Z8: Booked_CTV | AB8: Booked_CTV | AC8: Booked_CTV | AD8: Booked_CTV | AE8: Booked_CTV | AF8: Booked_CTV | AH8: Booked_CTV | AI8: Booked_CTV
A9: 6 | B9: STD-PNL | C9: 601 | D9: 2 | E9: Booked_CTV | F9: Booked_CTV | G9: Booked_BNB | H9: Booked_BNB | I9: Booked_BNB | K9: Booked_CTV | M9: Booked_CTV | N9: Booked_CTV | O9: Booked_CTV | X9: Booked_CTV | Y9: Booked_CTV | Z9: Booked_CTV | AB9: Booked_CTV | AC9: Booked_CTV | AD9: Booked_CTV | AE9: Booked_CTV | AF9: Booked_CTV | AG9: Booked_CTV | AH9: Booked_CTV | AI9: Booked_CTV
A10: 7 | B10: SUP-PNL | C10: 102 | D10: 2 | E10: Booked_CTV | F10: Booked_CTV | G10: Booked_CTV | P10: Booked_Ag | Q10: Booked_Ag | Z10: Booked_CTV | AI10: Booked_CTV
A11: 8 | B11: SUP-PNL | C11: 202 | D11: 2 | F11: Booked_CTV | G11: Booked_CTV | J11: Booked_CTV | S11: Booked_CTV | T11: Booked_CTV | U11: Booked_CTV | V11: Booked_CTV | W11: Booked_CTV | X11: Booked_CTV | Z11: Booked_CTV | AA11: Booked_CTV | AB11: Booked_CTV | AC11: Booked_CTV | AD11: Booked_CTV | AE11: Booked_CTV | AF11: Booked_CTV | AI11: Booked_CTV
A12: 9 | B12: SUP-PNL | C12: 302 | D12: 2 | E12: Booked_BNB | F12: Booked_BNB | G12: Booked_BNB | J12: Booked_CTV | K12: Booked_CTV | N12: Booked_CTV | U12: Booked_CTV | W12: Booked_CTV | Y12: Booked_CTV | Z12: Booked_BNB | AA12: Booked_BNB | AB12: Booked_BNB | AC12: Booked_BNB | AI12: Booked_CTV
A13: 10 | B13: SUP-PNL | C13: 402 | D13: 2 | E13: Booked_CTV | F13: Booked_BK | G13: Booked_CTV | H13: Booked_CTV | I13: Booked_CTV | M13: Booked_CTV | N13: Booked_CTV | R13: Booked_CTV | Y13: Booked_CTV | Z13: Booked_CTV | AA13: Booked_CTV | AB13: Booked_CTV | AC13: Booked_CTV | AD13: Booked_CTV | AE13: Booked_CTV | AF13: Booked_CTV
A14: 11 | B14: SUP-Q-PNL | C14: 502 | D14: 2 | E14: Booked_CTV | F14: Booked_Ag | G14: Booked_Ag | H14: Booked_Ag | I14: Booked_Ag | L14: Booked_CTV | M14: Booked_CTV | Q14: Booked_CTV | R14: Booked_CTV | S14: Booked_CTV | T14: Booked_CTV | U14: Booked_CTV | V14: Booked_CTV | W14: Booked_CTV | X14: Booked_CTV | Y14: Booked_CTV | Z14: Booked_CTV | AA14: Booked_CTV | AB14: Booked_CTV | AC14: Booked_CTV | AD14: Booked_CTV | AE14: Booked_CTV
A15: 12 | B15: SUP-Q-PNL | C15: 602 | D15: 2 | E15: Booked_CTV | F15: Booked_KL | G15: Booked_KL | H15: Booked_KL | R15: Booked_CTV | S15: Booked_CTV | T15: Booked_CTV | V15: Booked_CTV | W15: Booked_CTV | X15: Booked_CTV | AC15: Booked_CTV | AD15: Booked_Ex | AE15: Booked_Ex | AG15: Booked_CTV | AH15: Booked_CTV | AI15: Booked_CTV
A16: 13 | B16: SUP-Q-PNL | C16: 702 | D16: 2 | G16: Booked_CTV | H16: Booked_CTV | AC16: Booked_CTV | AD16: Booked_CTV | AE16: Booked_CTV | AF16: Booked_CTV
A17: 14 | B17: DELUXE-PNL | C17: 103 | D17: 2 | I17: Booked_CTV | J17: Booked_CTV | K17: Booked_CTV | R17: Booked_CTV
A18: 15 | B18: DELUXE-PNL | C18: 203 | D18: 2 | I18: Booked_CTV | J18: Booked_CTV | K18: Booked_CTV | N18: Booked_CTV | R18: Booked_Ex | S18: Booked_Ex | T18: Booked_Ex | U18: Booked_Ex | V18: Booked_Ex | W18: Booked_Ex | X18: Booked_Ex | AE18: Booked_BNB | AF18: Booked_BNB
A19: 16 | B19: DELUXE-PNL | C19: 303 | D19: 2 | G19: Booked_CTV | I19: Booked_CTV | J19: Booked_CTV | K19: Booked_CTV | R19: Booked_CTV | S19: Booked_Ex | T19: Booked_Ex | U19: Booked_BNB | V19: Booked_BNB | W19: Booked_BNB | X19: Booked_Ag
A20: 17 | B20: DELUXE-PNL | C20: 403 | D20: 2 | G20: Booked_CTV | H20: Booked_CTV | I20: Booked_CTV | T20: Booked_CTV | U20: Booked_CTV | V20: Booked_CTV | W20: Booked_CTV | Y20: Booked_CTV | Z20: Booked_CTV | AA20: Booked_CTV | AD20: Booked_CTV | AE20: Booked_CTV | AF20: Booked_CTV | AG20: Booked_CTV | AH20: Booked_CTV | AI20: Booked_CTV
A21: 18 | B21: DELUXE-PNL | C21: 503 | D21: 2 | G21: Booked_CTV | H21: Booked_CTV | I21: Booked_CTV | N21: Booked_CTV | W21: Booked_Ex | Y21: Booked_CTV | Z21: Booked_CTV | AA21: Booked_CTV | AB21: Booked_CTV | AD21: Booked_CTV | AE21: Booked_CTV | AF21: Booked_CTV | AH21: Booked_CTV
A22: 19 | B22: DELUXE-PNL | C22: 603 | D22: 2 | E22: Booked_CTV | F22: Booked_CTV | G22: Booked_CTV | H22: Booked_CTV | I22: Booked_CTV | J22: Booked_CTV | M22: Booked_BK | N22: Booked_BK | O22: Booked_BK | U22: Booked_CTV | X22: Booked_Ag | Y22: Booked_Ag | Z22: Booked_Ag | AA22: Booked_CTV | AB22: Booked_CTV | AD22: Booked_CTV | AI22: Booked_CTV
A23: 20 | B23: DELUXE-PNL | C23: 703 | D23: 2 | X23: Lock | Y23: Lock | Z23: Lock | AA23: Lock | AB23: Lock | AC23: Lock | AD23: Lock | AE23: Lock | AF23: Lock | AG23: Lock | AH23: Lock | AI23: Lock
A24: 21 | B24: MB-PNL | C24: MB-PNL | D24: 1 | E24: Lock | F24: Lock | G24: Lock | H24: Lock | I24: Lock | J24: Lock | K24: Lock | L24: Lock | M24: Lock | N24: Lock | O24: Lock | P24: Lock | Q24: Lock | R24: Lock | S24: Lock | T24: Lock | U24: Lock | V24: Lock | W24: Lock | X24: Lock | Y24: Lock | Z24: Lock | AA24: Lock | AB24: Lock | AC24: Lock | AD24: Lock | AE24: Lock | AF24: Lock | AG24: Lock | AH24: Lock | AI24: Lock
G27: Room sold by | K27: Room Empty | Q27: Room Analyst
B28: TOTAL CAPACITY | C28: Day | D28: Week | E28: Month | G28: Room Type | H28: Day | I28: Week | J28: Month | K28: Room Type | L28: Day | M28: Week | N28: Month | Q28: TOTAL CAPACITY | R28: Day | S28: Month | T28: Room sold | U28: Occupancy
B29: Total room: | C29: 21 | D29: =C29*7 -> 147 | E29: =C29*31 -> 651 | H29: 45505 | I29: 6/8 - 12/8 | J29: August | L29: 45505 | M29: 6/8 - 12/8 | N29: August | Q29: Total room: | R29: 20 | S29: 651 | T29: =SUM(T30:T33) -> 284 | U29: =T29/S29 -> 0.43625192
B30: STD-PNL | C30: 6 | D30: =C30*7 -> 42 | E30: =C30*31 -> 186 | G30: STD-PNL | H30: =COUNTA(E4:E9) -> 4 | I30: =COUNTA(J4:P9) -> 24 | J30: =COUNTA(E4:AI9) -> 112 | K30: STD-PNL | L30: =COUNTBLANK(E4:E9) -> 2 | M30: =COUNTBLANK(J4:P9) -> 18 | N30: =COUNTBLANK(E4:AI9) -> 74 | Q30: STD-PNL | R30: 6 | S30: 186 | T30: 112 | U30: =T30/S30 -> 0.60215054
B31: SUP-PNL | C31: 4 | D31: =C31*7 -> 28 | E31: =C31*31 -> 124 | G31: SUP-PNL | H31: =COUNTA(E10:E13) -> 3 | J31: =COUNTA(E10:AI13) -> 54 | K31: SUP-PNL | L31: =COUNTBLANK(I10:I14) -> 3 | N31: =COUNTBLANK(E10:AI13) -> 70 | Q31: SUP-PNL | R31: 4 | S31: 124 | T31: 54 | U31: =T31/S31 -> 0.43548387
B32: SUP-Q-PNL | C32: 3 | D32: =C32*7 -> 21 | E32: =C32*31 -> 93 | G32: SUP-Q-PNL | H32: =COUNTA(E14:E16) -> 2 | J32: =COUNTA(E14:AI16) -> 44 | K32: SUP-Q-PNL | L32: =COUNTBLANK(I14:I16) -> 2 | N32: =COUNTBLANK(E14:AI16) -> 49 | Q32: SUP-Q-PNL | R32: 3 | S32: 93 | T32: 44 | U32: =T32/S32 -> 0.47311828
B33: DELUXE - PNL | C33: 7 | D33: =C33*7 -> 49 | E33: =C33*31 -> 217 | G33: DELUXE - PNL | H33: =COUNTA(E17:E23) -> 1 | J33: 74 | K33: DELUXE - PNL | L33: =COUNTBLANK(I17:I23) -> 1 | N33: =COUNTBLANK(E17:AI23) -> 131 | Q33: DELUXE - PNL | R33: 7 | S33: 217 | T33: 74 | U33: =T33/S33 -> 0.34101382
B34: MB - PNL | C34: 1 | D34: =C34*7 -> 7 | E34: =C34*31 -> 31 | G34: MB - PNL | H34: =COUNTA(E24) -> 1 | K34: MB - PNL | L34: =COUNTBLANK(I24) -> 0
G37: Room sold by channel
B38: Code | C38: Source | G38: Source | H38: Day | I38: Week | J38: Month | M38: Monthly Analyst
B39: Booked_BK | C39: Booking | G39: Booking | J39: =COUNTIF($E$4:$AI$24,B39) -> 11 | M39: Room Type | N39: Total Month | O39: Booking | P39: Agoda | Q39: Airbnb | R39: Staff | S39: A26 web | T39: Facebook | U39: Walkin | V39: Expedia | W39: Traveloka | X39: Travel Agent | Y39: Klook
B40: Booked_Ag | C40: Agoda | G40: Agoda | J40: =COUNTIF($E$4:$AI$24,B40) -> 24 | M40: STD-PNL | N40: 112 | O40: =COUNTIF($E$4:$AI$9,O44) -> 7 | P40: =COUNTIF($E$4:$AI$9,P44) -> 14 | Q40: =COUNTIF($E$4:$AI$9,Q44) -> 3 | R40: =COUNTIF($E$4:$AI$9,R44) -> 88 | S40: =COUNTIF($E$4:$AI$9,S44) -> 0 | T40: =COUNTIF($E$4:$AI$9,T44) -> 0 | U40: =COUNTIF($E$4:$AI$9,U44) -> 0 | V40: =COUNTIF($E$4:$AI$9,V44) -> 0 | ... Y40: =COUNTIF($E$4:$AI$9,Y44) -> 0
B41: Booked_BNB | C41: Airbnb | G41: Airbnb | J41: =COUNTIF($E$4:$AI$24,B41) -> 15 | M41: SUP-PNL | N41: 54 | O41: =COUNTIF($E$10:$AI$13,O44) -> 1 | P41: =COUNTIF($E$10:$AI$13,P44) -> 2 | Q41: =COUNTIF($E$10:$AI$13,Q44) -> 7 | R41: =COUNTIF($E$10:$AI$13,R44) -> 44 | S41: =COUNTIF($E$10:$AI$13,S44) -> 0 | T41: =COUNTIF($E$10:$AI$13,T44) -> 0 | U41: =COUNTIF($E$10:$AI$13,U44) -> 0 | V41: =COUNTIF($E$10:$AI$13,V44) -> 0 | ... Y41: =COUNTIF($E$10:$AI$13,Y44) -> 0
B42: Booked_CTV | C42: Staff | G42: Staff | J42: =COUNTIF($E$4:$AI$24,B42) -> 219 | M42: SUP-Q-PNL | N42: 44 | O42: =COUNTIF($E$14:$AI$16,O44) -> 0 | P42: =COUNTIF($E$14:$AI$16,P44) -> 4 | Q42: =COUNTIF($E$14:$AI$16,Q44) -> 0 | R42: =COUNTIF($E$14:$AI$16,R44) -> 35 | S42: =COUNTIF($E$14:$AI$16,S44) -> 0 | T42: =COUNTIF($E$14:$AI$16,T44) -> 0 | U42: =COUNTIF($E$14:$AI$16,U44) -> 0 | V42: =COUNTIF($E$14:$AI$16,V44) -> 2 | ... Y42: =COUNTIF($E$14:$AI$16,Y44) -> 3
B43: Booked_Web | C43: A26 web | G43: A26 web | J43: =COUNTIF($E$4:$AI$24,B43) -> 0 | M43: DELUXE - PNL | N43: 86 | O43: =COUNTIF($E$17:$AI$23,O44) -> 3 | P43: =COUNTIF($E$17:$AI$23,P44) -> 4 | Q43: =COUNTIF($E$17:$AI$23,Q44) -> 5 | R43: =COUNTIF($E$17:$AI$23,R44) -> 52 | S43: =COUNTIF($E$17:$AI$23,S44) -> 0 | T43: =COUNTIF($E$17:$AI$23,T44) -> 0 | U43: =COUNTIF($E$17:$AI$23,U44) -> 0 | V43: =COUNTIF($E$17:$AI$23,V44) -> 10 | ... Y43: =COUNTIF($E$17:$AI$23,Y44) -> 0
B44: Booked_FB | C44: Facebook | G44: Facebook | J44: =COUNTIF($E$4:$AI$24,B44) -> 0 | O44: Booked_BK | P44: Booked_Ag | Q44: Booked_BNB | R44: Booked_CTV | S44: Booked_Web | T44: Booked_FB | U44: Booked_WK | V44: Booked_Ex | W44: Booked_LK | X44: Booked_TA | Y44: Booked_KL
...

Sheet June
B1: A26 Benthanh | E1: June 2024
E2: Sat | F2: Sun | G2: Mon | H2: Tue | I2: Wed | J2: Thu | K2: Fri | L2: Sat | M2: Sun | N2: Mon | O2: Tue | P2: Wed | Q2: Thu | R2: Fri | S2: Sat | T2: Sun | U2: Mon | V2: Tue | W2: Wed | X2: Thu | Y2: Fri | Z2: Sat | AA2: Sun | AB2: Mon | AC2: Tue | AD2: Wed | AE2: Thu | AF2: Fri | AG2: Sat | AH2: Sun
A3: No | B3: Room type | C3: Room No | D3: Capacity (pax) | E3: 45444 | F3: 45445 | G3: 45446 | H3: 45447 | I3: 45448 | J3: 45449 | K3: 45450 | L3: 45451 | M3: 45452 | N3: 45453 | O3: 45454 | P3: 45455 | Q3: 45456 | R3: 45457 | S3: 45458 | T3: 45459 | U3: 45460 | V3: 45461 | W3: 45462 | X3: 45463 | Y3: 45464 | Z3: 45465 | AA3: 45466 | AB3: 45467 | AC3: 45468 | AD3: 45469 | AE3: 45470 | AF3: 45471 | AG3: 45472 | AH3: 45473
A4: 1 | B4: STD-PNL | C4: 101 | D4: 2 | E4: Booked_CTV | M4: Booked_CTV | Q4: Booked_CTV | R4: Booked_Ag
A5: 2 | B5: STD-PNL | C5: 201 | D5: 2 | E5: Booked_CTV | J5: Booked_Web | N5: Booked_CTV | O5: Booked_CTV | P5: Booked_CTV | Q5: Booked_CTV | R5: Booked_CTV | S5: Booked_CTV | T5: Booked_CTV | W5: Booked_CTV | X5: Booked_Ag | Z5: Booked_CTV | AA5: Booked_CTV | AB5: Booked_CTV | AC5: Booked_CTV | AD5: Booked_CTV | AE5: Booked_CTV | AG5: Booked_Ag | AH5: Booked_Ag
A6: 3 | B6: STD-PNL | C6: 301 | D6: 2 | E6: Booked_Web | H6: Booked_CTV | I6: Booked_CTV | J6: Booked_CTV | L6: Booked_CTV | M6: Booked_CTV | N6: Booked_CTV | O6: Booked_CTV | P6: Booked_Ag | Q6: Booked_CTV | R6: Booked_Ag | S6: Booked_Ag | T6: Booked_Ag | U6: Booked_Web | V6: Booked_Web | W6: Booked_Web | X6: Booked_Ag | Y6: Booked_Ag | Z6: Booked_Ag | AA6: Booked_Ag | AB6: Booked_Ag | AC6: Booked_Ag | AD6: Booked_Ag | AE6: Booked_CTV | AF6: Booked_CTV | AG6: Booked_CTV | AH6: Booked_CTV
A7: 4 | B7: STD-PNL | C7: 401 | D7: 2 | E7: Booked_CTV | F7: Booked_CTV | H7: Booked_CTV | I7: Booked_CTV | J7: Booked_CTV | L7: Booked_CTV | M7: Booked_CTV | N7: Booked_CTV | P7: Booked_CTV | Q7: Booked_CTV | R7: Booked_CTV | S7: Booked_CTV | T7: Booked_CTV | U7: Booked_CTV | W7: Booked_CTV | X7: Booked_CTV | Y7: Booked_CTV | Z7: Booked_CTV | AA7: Booked_CTV | AB7: Booked_CTV | AC7: Booked_CTV | AD7: Booked_BNB | AE7: Booked_BNB | AG7: Booked_Ag | AH7: Booked_CTV
A8: 5 | B8: STD-PNL | C8: 501 | D8: 2 | E8: Booked_Web | H8: Booked_CTV | J8: Booked_CTV | L8: Booked_CTV | M8: Booked_CTV | P8: Booked_CTV | Q8: Booked_CTV | R8: Booked_CTV | S8: Booked_CTV | T8: Booked_Ag | W8: Booked_Ag | X8: Booked_Ag | Y8: Booked_CTV | AA8: Booked_CTV | AC8: Booked_CTV | AD8: Booked_CTV | AE8: Booked_CTV | AF8: Booked_CTV | AG8: Booked_CTV | AH8: Booked_CTV
A9: 6 | B9: STD-PNL | C9: 601 | D9: 2 | F9: Booked_CTV | H9: Booked_CTV | J9: Booked_Web | K9: Booked_CTV | M9: Booked_CTV | N9: Booked_CTV | Q9: Booked_CTV | R9: Booked_CTV | S9: Booked_Ag | T9: Booked_CTV | U9: Booked_Ag | V9: Booked_Ag | W9: Booked_CTV | X9: Booked_CTV | Y9: Booked_CTV | Z9: Booked_Ag | AA9: Booked_Ag | AB9: Booked_Ag | AC9: Booked_Ag | AD9: Booked_Ag | AE9: Booked_Ag | AF9: Booked_Ag | AG9: Booked_Ag | AH9: Booked_Ag
A10: 7 | B10: SUP-PNL | C10: 102 | D10: 2 | F10: Booked_CTV | H10: Booked_CTV | I10: Booked_CTV | K10: Booked_Ag | Q10: Booked_CTV | R10: Booked_CTV | S10: Booked_CTV | T10: Booked_CTV | AB10: Booked_CTV | AC10: Booked_CTV | AE10: Booked_CTV | AG10: Booked_CTV
A11: 8 | B11: SUP-PNL | C11: 202 | D11: 2 | F11: Booked_BK | H11: Booked_CTV | J11: Booked_Web | R11: Booked_Ag | S11: Booked_Ag | U11: Booked_CTV | X11: Booked_Ag | Y11: Booked_CTV | Z11: Booked_CTV | AB11: Booked_CTV | AC11: Booked_CTV | AD11: Booked_CTV | AE11: Booked_CTV | AF11: Booked_CTV | AG11: Booked_CTV | AH11: Booked_CTV
A12: 9 | B12: SUP-PNL | C12: 302 | D12: 2 | E12: Booked_CTV | G12: Booked_BK | H12: Booked_BK | I12: Booked_BK | J12: Booked_CTV | L12: Booked_CTV | O12: Booked_CTV | P12: Booked_Ag | Q12: Booked_Ag | R12: Booked_Ag | S12: Booked_Ag | V12: Booked_CTV | Y12: Booked_CTV | Z12: Booked_CTV | AA12: Booked_CTV | AB12: Booked_CTV | AC12: Booked_CTV | AD12: Booked_CTV | AE12: Booked_CTV | AF12: Booked_BK | AG12: Booked_BK | AH12: Booked_CTV
A13: 10 | B13: SUP-PNL | C13: 402 | D13: 2 | K13: Booked_CTV | O13: Booked_CTV | P13: Booked_CTV | Q13: Booked_CTV | R13: Booked_CTV | S13: Booked_CTV | T13: Booked_CTV | U13: Booked_CTV | X13: Booked_CTV | Z13: Booked_Ag | AA13: Booked_Ag | AB13: Booked_Ag | AC13: Booked_Ag | AD13: Booked_CTV | AE13: Booked_Ag | AF13: Booked_Ag | AG13: Booked_CTV | AH13: Booked_CTV
A14: 11 | B14: SUP-Q-PNL | C14: 502 | D14: 2 | E14: Booked_FB | H14: Booked_CTV | J14: Booked_Ag | L14: Booked_CTV | N14: Booked_BNB | O14: Booked_CTV | Q14: Booked_CTV | R14: Booked_CTV | S14: Booked_CTV | T14: Booked_CTV | U14: Booked_CTV | X14: Booked_BNB | Y14: Booked_BNB | AA14: Booked_Ag | AE14: Booked_BK | AF14: Booked_CTV | AG14: Booked_CTV | AH14: Booked_CTV
A15: 12 | B15: SUP-Q-PNL | C15: 602 | D15: 2 | F15: Booked_BNB | J15: Booked_BNB | K15: Booked_BNB | M15: Booked_CTV | N15: Booked_Web | O15: Booked_Web | P15: Booked_Ag | Q15: Booked_Ag | R15: Booked_CTV | U15: Booked_CTV | W15: Booked_BK | Z15: Booked_Ag | AA15: Booked_CTV | AC15: Booked_CTV | AE15: Booked_CTV | AF15: Booked_CTV | AH15: Booked_CTV
A16: 13 | B16: SUP-Q-PNL | C16: 702 | D16: 2
A17: 14 | B17: DELUXE-PNL | C17: 103 | D17: 2 | AF17: Booked_CTV
A18: 15 | B18: DELUXE-PNL | C18: 203 | D18: 2 | L18: Booked_CTV | M18: Booked_CTV | N18: Booked_CTV | O18: Booked_CTV | Q18: Booked_CTV | S18: Booked_CTV | T18: Booked_CTV | AG18: Booked_Web | AH18: Booked_Web
A19: 16 | B19: DELUXE-PNL | C19: 303 | D19: 2 | G19: Booked_CTV | I19: Booked_CTV | L19: Booked_CTV | M19: Booked_CTV | N19: Booked_CTV | O19: Booked_CTV | Q19: Booked_CTV | U19: Booked_Web | V19: Booked_Web | W19: Booked_Web | Z19: Booked_CTV | AA19: Booked_CTV | AB19: Booked_CTV | AG19: Booked_CTV | AH19: Booked_CTV
A20: 17 | B20: DELUXE-PNL | C20: 403 | D20: 2 | J20: Booked_CTV | K20: Booked_Web | L20: Booked_Web | M20: Booked_Web | O20: Booked_Web | P20: Booked_Web | Q20: Booked_Web | R20: Booked_BNB | S20: Booked_BNB | T20: Booked_BNB | U20: Booked_Web | V20: Booked_Web | W20: Booked_Web | Z20: Booked_CTV | AA20: Booked_CTV | AG20: Booked_BNB | AH20: Booked_BNB
A21: 18 | B21: DELUXE-PNL | C21: 503 | D21: 2 | H21: Booked_CTV | J21: Booked_CTV | K21: Booked_CTV | L21: Booked_CTV | N21: Booked_CTV | O21: Booked_CTV | P21: Booked_BNB | R21: Booked_CTV | S21: Booked_CTV | T21: Booked_CTV | U21: Booked_CTV | V21: Booked_CTV | W21: Booked_BNB | X21: Booked_BNB | Y21: Booked_CTV | AE21: Booked_CTV | AF21: Booked_CTV | AG21: Booked_CTV | AH21: Booked_CTV
A22: 19 | B22: DELUXE-PNL | C22: 603 | D22: 2 | J22: Booked_CTV | K22: Booked_CTV | L22: Booked_CTV | M22: Booked_CTV | N22: Booked_CTV | P22: Booked_BNB | Q22: Booked_BNB | R22: Booked_BNB | S22: Booked_BNB | T22: Booked_BNB | U22: Booked_BNB | V22: Booked_BNB | W22: Booked_BNB | X22: Booked_BNB | Y22: Booked_BNB | Z22: Booked_BNB | AD22: Booked_CTV | AE22: Booked_CTV | AF22: Booked_CTV | AG22: Booked_CTV | AH22: Booked_CTV
A23: 20 | B23: DELUXE-PNL | C23: 703 | D23: 2 | M23: Booked_CTV | N23: Booked_CTV | O23: Booked_CTV | AC23: Booked_CTV | AD23: Booked_CTV | AE23: Booked_CTV
A24: 21 | B24: MB-PNL | C24: MB-PNL | D24: 1 | E24: Lock | F24: Lock | G24: Lock | H24: Lock | I24: Lock | J24: Lock | K24: Lock | L24: Lock | M24: Lock | N24: Lock | O24: Lock | P24: Lock | Q24: Lock | R24: Lock | S24: Lock | T24: Lock | U24: Lock | V24: Lock | W24: Lock | X24: Lock | Y24: Lock | Z24: Lock | AA24: Lock | AB24: Lock | AC24: Lock | AD24: Lock | AE24: Lock | AF24: Lock | AG24: Lock | AH24: Lock
G27: Room sold by Type | K27: Room Empty | Q27: Room Analyst
B28: TOTAL CAPACITY | C28: Day | D28: Week | E28: Month | G28: Room Type | H28: Day | I28: Week | J28: Month | K28: Room Type | L28: Day | M28: Week | N28: Month | Q28: TOTAL CAPACITY | R28: Day | S28: Month | T28: Room sold | U28: Occupancy
B29: Total room: | C29: 21 | D29: =C29*7 -> 147 | E29: =C29*30 -> 630 | H29: 45444 | I29: 6/6 - 12/6 | J29: June | L29: 45444 | M29: 6/6 - 12/6 | N29: June | Q29: Total room: | R29: =SUM(R30:R33) -> 20 | S29: =R29*30 -> 600 | T29: =SUM(T30:T33) -> 310 | U29: =T29/S29 -> 0.51666667
B30: STD-PNL | C30: 6 | D30: =C30*7 -> 42 | E30: =C30*30 -> 180 | G30: STD-PNL | H30: =COUNTA(E4:E9) -> 5 | I30: =COUNTA(J4:P9) -> 24 | J30: =COUNTA('Visualize-6-months'!D4) -> 1 | K30: STD-PNL | L30: =COUNTBLANK(E4:E9) -> 1 | M30: =COUNTBLANK(J4:P9) -> 18 | N30: =COUNTBLANK(E4:AH9) -> 61 | Q30: STD-PNL | R30: 6 | S30: =R30*30 -> 180 | T30: 119 | U30: =T30/S30 -> 0.66111111
B31: SUP-PNL | C31: 4 | D31: =C31*7 -> 28 | E31: =C31*30 -> 120 | G31: SUP-PNL | H31: =COUNTA(E10:E13) -> 1 | J31: =COUNTA(E10:AH13) -> 68 | K31: SUP-PNL | L31: =COUNTBLANK(I10:I14) -> 3 | N31: =COUNTBLANK(E10:AH13) -> 52 | Q31: SUP-PNL | R31: 4 | S31: =R31*30 -> 120 | T31: 68 | U31: =T31/S31 -> 0.56666667
B32: SUP-Q-PNL | C32: 3 | D32: =C32*7 -> 21 | E32: =C32*30 -> 90 | G32: SUP-Q-PNL | H32: =COUNTA(E14:E16) -> 1 | J32: =COUNTA(E14:AH16) -> 35 | K32: SUP-Q-PNL | L32: =COUNTBLANK(I14:I16) -> 3 | N32: =COUNTBLANK(E14:AH16) -> 55 | Q32: SUP-Q-PNL | R32: 3 | S32: =R32*30 -> 90 | T32: 35 | U32: =T32/S32 -> 0.38888889
B33: DELUXE - PNL | C33: 7 | D33: =C33*7 -> 49 | E33: =C33*30 -> 210 | G33: DELUXE - PNL | H33: =COUNTA(E17:E23) -> 0 | J33: =COUNTA(E17:AH23) -> 88 | K33: DELUXE - PNL | L33: =COUNTBLANK(I17:I23) -> 6 | N33: =COUNTBLANK(E17:AH23) -> 122 | Q33: DELUXE - PNL | R33: 7 | S33: =R33*30 -> 210 | T33: 88 | U33: =T33/S33 -> 0.41904762
B34: MB - PNL | C34: 1 | D34: =C34*7 -> 7 | E34: =C34*30 -> 30 | G34: MB - PNL | K34: MB - PNL | L34: =COUNTBLANK(I24) -> 0
G37: Room sold by channel
B38: Code | C38: Source | G38: Source | H38: Day | I38: Week | J38: Month | M38: Monthly Analyst
B39: Booked_BK | C39: Booking | G39: Booking | J39: =COUNTIF($E$4:$AH$24,B39) -> 8 | M39: Room Type | N39: Total Month | O39: Booking | P39: Agoda | Q39: Airbnb | R39: Staff | S39: A26 web | T39: Facebook | U39: Walkin | V39: Expedia | W39: Traveloka | X39: Travel Agent | Y39: Klook
B40: Booked_Ag | C40: Agoda | G40: Agoda | J40: =COUNTIF($E$4:$AH$24,B40) -> 50 | M40: STD-PNL | N40: 119 | O40: =COUNTIF($E$4:$AH$9,O44) -> 0 | P40: =COUNTIF($E$4:$AH$9,P44) -> 31 | Q40: =COUNTIF($E$4:$AH$9,Q44) -> 2 | R40: =COUNTIF($E$4:$AH$9,R44) -> 79 | S40: =COUNTIF($E$4:$AH$9,S44) -> 7 | T40: =COUNTIF($E$4:$AH$9,T44) -> 0 | U40: =COUNTIF($E$4:$AH$9,U44) -> 0 | V40: =COUNTIF($E$4:$AH$9,V44) -> 0 | ... Y40: =COUNTIF($E$4:$AH$9,Y44) -> 0
B41: Booked_BNB | C41: Airbnb | G41: Airbnb | J41: =COUNTIF($E$4:$AH$24,B41) -> 27 | M41: SUP-PNL | N41: 68 | O41: =COUNTIF($E$10:$AH$13,O44) -> 6 | P41: =COUNTIF($E$10:$AH$13,P44) -> 14 | Q41: =COUNTIF($E$10:$AH$13,Q44) -> 0 | R41: =COUNTIF($E$10:$AH$13,R44) -> 47 | S41: =COUNTIF($E$10:$AH$13,S44) -> 1 | T41: =COUNTIF($E$10:$AH$13,T44) -> 0 | U41: =COUNTIF($E$10:$AH$13,U44) -> 0 | V41: =COUNTIF($E$10:$AH$13,V44) -> 0 | ... Y41: =COUNTIF($E$10:$AH$13,Y44) -> 0
B42: Booked_CTV | C42: Staff | G42: Staff | J42: =COUNTIF($E$4:$AH$24,B42) -> 200 | M42: SUP-Q-PNL | N42: 35 | O42: =COUNTIF($E$14:$AH$16,O44) -> 2 | P42: =COUNTIF($E$14:$AH$16,P44) -> 5 | Q42: =COUNTIF($E$14:$AH$16,Q44) -> 6 | R42: =COUNTIF($E$14:$AH$16,R44) -> 19 | S42: =COUNTIF($E$14:$AH$16,S44) -> 2 | T42: =COUNTIF($E$14:$AH$16,T44) -> 1 | U42: =COUNTIF($E$14:$AH$16,U44) -> 0 | V42: =COUNTIF($E$14:$AH$16,V44) -> 0 | ... Y42: =COUNTIF($E$14:$AH$16,Y44) -> 0
